python: can't open file 'speedtestserver.pyd': [Errno 2] No such file or directory
 * Running on http://192.168.0.39:5000/ (Press CTRL+C to quit)
24.131.39.32 - - [15/Jul/2016 07:49:34] "GET / HTTP/1.1" 200 -
66.249.85.147 - - [15/Jul/2016 10:47:24] "GET / HTTP/1.1" 200 -
66.249.85.147 - - [15/Jul/2016 10:47:25] "GET /favicon.ico HTTP/1.1" 404 -
 * Running on http://192.168.0.39:5000/ (Press CTRL+C to quit)
66.249.88.23 - - [15/Jul/2016 18:39:25] "GET / HTTP/1.1" 200 -
66.249.88.34 - - [15/Jul/2016 18:39:26] "GET /tests HTTP/1.1" 200 -
66.249.88.34 - - [15/Jul/2016 18:39:26] "GET /favicon.ico HTTP/1.1" 404 -
66.249.83.247 - - [15/Jul/2016 18:55:25] "GET / HTTP/1.1" 200 -
66.249.83.244 - - [15/Jul/2016 18:55:25] "GET /favicon.ico HTTP/1.1" 404 -
24.131.39.32 - - [15/Jul/2016 19:21:27] "GET / HTTP/1.1" 200 -
66.249.88.34 - - [16/Jul/2016 09:36:58] "GET /tests HTTP/1.1" 200 -
66.249.88.45 - - [16/Jul/2016 09:36:58] "GET / HTTP/1.1" 200 -
66.249.88.34 - - [16/Jul/2016 09:36:58] "GET /favicon.ico HTTP/1.1" 404 -
66.249.88.23 - - [16/Jul/2016 09:36:58] "GET /favicon.ico HTTP/1.1" 404 -
66.249.85.139 - - [16/Jul/2016 16:15:01] "GET / HTTP/1.1" 200 -
66.249.85.147 - - [16/Jul/2016 16:15:01] "GET /favicon.ico HTTP/1.1" 404 -
24.131.39.32 - - [16/Jul/2016 16:36:09] "GET / HTTP/1.1" 200 -
24.131.39.32 - - [16/Jul/2016 16:36:19] "GET / HTTP/1.1" 200 -
24.131.39.32 - - [16/Jul/2016 16:36:22] "GET /tests HTTP/1.1" 200 -
Traceback (most recent call last):
  File "speedtestserver.py", line 61, in <module>
    app.run(host="192.168.0.39", port = 5000)
  File "/usr/local/lib/python2.7/dist-packages/flask/app.py", line 843, in run
    run_simple(host, port, self, **options)
  File "/usr/local/lib/python2.7/dist-packages/werkzeug/serving.py", line 694, in run_simple
    inner()
  File "/usr/local/lib/python2.7/dist-packages/werkzeug/serving.py", line 659, in inner
    srv.serve_forever()
  File "/usr/local/lib/python2.7/dist-packages/werkzeug/serving.py", line 499, in serve_forever
    HTTPServer.serve_forever(self)
  File "/usr/lib/python2.7/SocketServer.py", line 238, in serve_forever
    self._handle_request_noblock()
  File "/usr/lib/python2.7/SocketServer.py", line 297, in _handle_request_noblock
    self.handle_error(request, client_address)
  File "/usr/lib/python2.7/SocketServer.py", line 295, in _handle_request_noblock
    self.process_request(request, client_address)
  File "/usr/lib/python2.7/SocketServer.py", line 321, in process_request
    self.finish_request(request, client_address)
  File "/usr/lib/python2.7/SocketServer.py", line 334, in finish_request
    self.RequestHandlerClass(request, client_address, self)
  File "/usr/lib/python2.7/SocketServer.py", line 657, in __init__
    self.finish()
  File "/usr/lib/python2.7/SocketServer.py", line 716, in finish
    self.wfile.close()
  File "/usr/lib/python2.7/socket.py", line 279, in close
    self.flush()
  File "/usr/lib/python2.7/socket.py", line 303, in flush
    self._sock.sendall(view[write_offset:write_offset+buffer_size])
socket.error: [Errno 32] Broken pipe
